<?xml version="1.0"?>
<robot name="3D_SLIP">
  
    <!-- Colors -->
    <material name="orange">
        <color rgba="1.0 0.424 0.047 1.0"/>
    </material>
    <material name="black">
        <color rgba="0 0 0 1.0"/>
    </material>
    <material name="grey">
        <color rgba="0.2 0.2 0.2 0.5"/>
    </material>
    <material name="white">
        <color rgba="1 1 1 0.5"/>
    </material>
    
    <!-- Link: COM Body -->
    <link name="body">
        <inertial>
            <origin xyz="0 0 0" rpy="0 0 0"/>
            <mass value="20"/>
            <inertia ixx="0.045" ixy="0" ixz="0" iyy="0.045" iyz="0" izz="0.045"/>
        </inertial>
        <visual>
            <origin xyz="0 0 0" rpy="0 0 0"/>
            <geometry>
                <mesh filename="../meshes/Body.OBJ"/>
            </geometry>
            <material name="orange"/>
        </visual>
        <collision>
            <origin xyz="0 0 0" rpy="0 0 0"/>
            <geometry>
                <sphere radius="0.075"/>
            </geometry>
        </collision>
    </link>
    
    <!-- Link: Intermmediate Leg Frames -->
    <link name="x_axis_leg"/>
    <link name="y_axis_leg"/>

    <!-- Link: Upper Leg -->
    <link name="leg_upper">
        <inertial>
            <origin xyz="0 0 0" rpy="0 0 0"/>
            <mass value="0.5"/>
            <inertia ixx="0.0001" ixy="0" ixz="0" iyy="0.0001" iyz="0" izz="0.0001"/>
        </inertial>
        <visual>
            <origin xyz="0 0 0" rpy="0 0 0"/>
            <geometry>
                <cylinder radius="0.025" length="0.3"/>
            </geometry>
            <material name="grey"/>
        </visual>
    </link>

    <!-- Joint: COM to Upper Leg -->
    <joint name="leg_roll" type="revolute">
        <origin xyz="0 0 0" rpy="0 0 0"/>
        <parent link="body"/>
        <child link="x_axis_leg"/>
        <axis xyz="1 0 0"/>
        <limit lower="-1.5708" upper="1.5708"/>
    </joint>
    <joint name="leg_pitch" type="revolute">
        <origin xyz="0 0 0" rpy="0 0 0"/>
        <parent link="x_axis_leg"/>
        <child link="y_axis_leg"/>
        <axis xyz="0 1 0"/>
        <limit lower="-1.5708" upper="1.5708"/>
    </joint>
    <joint name="body_to_upper_leg" type="fixed">
        <origin xyz="0 0 -0.15" rpy="0 0 0"/>
        <parent link="y_axis_leg"/>
        <child link="leg_upper"/>
        <axis xyz="0 1 0"/>
    </joint>

    <!-- Link: Lower Leg -->
    <link name="leg_lower">
        <inertial>
            <origin xyz="0 0 0" rpy="0 0 0"/>
            <mass value="0.5"/>
            <inertia ixx="0.0001" ixy="0" ixz="0" iyy="0.0001" iyz="0" izz="0.0001"/>
        </inertial>
        <visual>
            <origin xyz="0 0 0" rpy="0 0 0"/>
            <geometry>
                <cylinder radius="0.015" length="0.3"/>
            </geometry>
            <material name="white"/>
        </visual>
    </link>

    <!-- Joint: Upper Leg to Lower Leg -->
    <joint name="leg_prismatic" type="prismatic">
        <origin xyz="0 0 -0.15" rpy="0 0 0"/>
        <parent link="leg_upper"/>
        <child link="leg_lower"/>
        <axis xyz="0 0 1"/>
        <limit lower="-0.15" upper="0.15"/>
    </joint>

    <!-- Link: Foot -->
    <link name="foot">
        <inertial>
            <origin xyz="0 0 0" rpy="0 0 0"/>
            <mass value="0.1"/>
            <inertia ixx="0.0001" ixy="0" ixz="0" iyy="0.0001" iyz="0" izz="0.0001"/>
        </inertial>
        <visual>
            <origin xyz="0 0 0" rpy="0 0 0"/>
            <geometry>
                <sphere radius="0.025"/>
            </geometry>
            <material name="black"/>
        </visual>
        <collision>
            <origin xyz="0 0 0" rpy="0 0 0"/>
            <geometry>
                <sphere radius="0.025"/>
            </geometry>
        </collision>
    </link>

    <!-- Joint: Lower Leg to Foot -->
    <joint name="leg_to_foot" type="fixed">
        <origin xyz="0 0 -0.15" rpy="0 0 0"/>
        <parent link="leg_lower"/>
        <child link="foot"/>
    </joint>

</robot>