<mujoco model="3D_SLIP">
    <compiler angle="radian"/>

    <!-- Options for simulation -->
    <option timestep="0.01" integrator="RK4" gravity="0 0 -9.81"/>

    <!-- World body -->
    <worldbody>
        
        <!-- Ground plane -->
        <geom type="plane" pos="0 0 0" size="10 10 0.1" material="MatPlane"/>

        <!-- Body (top mass) -->
        <body name="body" pos="0 0 1">
            <geom name="body_geom" type="sphere" size="0.1" density="1000" rgba="0 0 1 1"/>
            <joint name="free_joint" type="free"/>
        </body>

        <!-- Leg (massless) -->
        <body name="leg" pos="0 0 0.5">
            <geom name="leg_geom" type="capsule" fromto="0 0 0 0 0 -1" size="0.05" rgba="0.5 0.5 0.5 1"/>
            <joint name="leg_spring" type="slide" axis="0 0 1" pos="0 0 -0.5" range="0.1 1.0"/>
        </body>

        <!-- Foot (contact point) -->
        <body name="foot" pos="0 0 0">
            <geom name="foot_geom" type="sphere" size="0.05" rgba="1 0 0 1"/>
        </body>
    </worldbody>

    <!-- Tendon for Spring between body and foot (acts like a spring constraint) -->
    <tendon>
        <spatial name="spring_tendon" stiffness="1000" damping="5">
            <site pos="0 0 1" body="body"/>  <!-- Attach at the body's center -->
            <site pos="0 0 0" body="foot"/>  <!-- Attach at the foot -->
        </spatial>
    </tendon>

    <!-- Actuation for the spring (optional if you want to control the leg) -->
    <actuator>
        <motor joint="leg_spring" ctrlrange="0 1" ctrllimited="true" gear="100"/>
    </actuator>

    <!-- Materials -->
    <asset>
        <texture name="texplane" type="2d" builtin="checker" width="512" height="512" rgb1="0.2 0.3 0.4" rgb2="0.1 0.2 0.3"/>
        <material name="MatPlane" texture="texplane" texrepeat="1 1" reflectance="0.3"/>
    </asset>

</mujoco>
