<?xml version="1.0"?>
<robot name="3D_SLIP">
  
  <!-- Body (mass at the top of the leg) -->
  <link name="body">
    <inertial>
      <mass value="1.0"/> <!-- Adjust mass as needed -->
      <inertia ixx="0.001" iyy="0.001" izz="0.001" ixy="0" ixz="0" iyz="0"/>
      <origin xyz="0 0 0"/>
    </inertial>
    <visual>
      <geometry>
        <sphere radius="0.1"/> <!-- Represents the body as a sphere -->
      </geometry>
      <material name="blue">
        <color rgba="0 0 1 1"/>
      </material>
    </visual>
    <collision>
      <geometry>
        <sphere radius="0.1"/>
      </geometry>
    </collision>
  </link>

  <!-- Leg -->
  <link name="leg">
    <visual>
      <geometry>
        <cylinder length="1.0" radius="0.05"/> <!-- Adjust leg length and radius -->
      </geometry>
      <material name="gray">
        <color rgba="0.5 0.5 0.5 1"/>
      </material>
    </visual>
    <collision>
      <geometry>
        <cylinder length="1.0" radius="0.05"/>
      </geometry>
    </collision>
  </link>

  <!-- Spring -->
  <link name="spring">
    <visual>
      <geometry>
        <cylinder length="1.0" radius="0.02"/> <!-- Adjust spring length and radius -->
      </geometry>
      <material name="green">
        <color rgba="0 1 0 1"/>
      </material>
    </visual>
  </link>

  <!-- Body to Leg joint -->
  <joint name="body_to_leg" type="continuous">
    <parent link="body"/>
    <child link="leg"/>
    <origin xyz="0 0 0" rpy="0 0 0"/>
    <axis xyz="0 1 0"/> <!-- Allows leg rotation -->
    <limit lower="-3.14159" upper="3.14159" effort="0" velocity="0"/>
  </joint>

  <!-- Leg to Ground Joint (Leg anchor point) -->
  <joint name="leg_to_ground" type="prismatic">
    <parent link="leg"/>
    <child link="spring"/>
    <origin xyz="0 0 -0.5" rpy="0 0 0"/>
    <axis xyz="0 0 1"/> <!-- Movement along z-axis -->
    <limit lower="0.1" upper="1.0" effort="1000" velocity="1.0"/> <!-- Prismatic movement constraints -->
  </joint>

  <!-- Foot (Contact point at the base of the leg) -->
  <link name="foot">
    <visual>
      <geometry>
        <sphere radius="0.05"/> <!-- Foot represented as a small sphere -->
      </geometry>
      <material name="red">
        <color rgba="1 0 0 1"/>
      </material>
    </visual>
    <collision>
      <geometry>
        <sphere radius="0.05"/>
      </geometry>
    </collision>
  </link>

  <!-- Spring to Foot Joint -->
  <joint name="spring_to_foot" type="fixed">
    <parent link="spring"/>
    <child link="foot"/>
    <origin xyz="0 0 -0.5" rpy="0 0 0"/>
  </joint>

</robot>
